<?xml version='1.0' encoding='utf-8'?>
<robot xmlns:xacro="http://www.ros.org/wiki/xacro" name="motoman_sia5f_arm">
  
	<xacro:property name="deg" value="0.017453293" /> 
  <xacro:property name="joint_damping" value="1.0" />

  <link name="base_link">
    <visual>
      <origin xyz="0 0 0" rpy="0 0 0" />
      <geometry>
        <mesh filename="file://$(find yaskawa_description_ros2)/meshes/visual/base.dae"/>
      </geometry>
    </visual>
    <collision>
      <origin xyz="0 0 0" rpy="0 0 0" />
      <geometry>
        <mesh filename="file://$(find yaskawa_description_ros2)/meshes/collision/base.dae"/>
      </geometry>
    </collision>
    <inertial>
      <!-- <origin rpy="0 0 0" xyz="-0.025918 -0.000376 0.076105"/> -->
      <mass value="9.23913043478"/>
      <inertia ixx="0.0378685009058" ixy="0" ixz="0" iyy="0.0465867830616" iyz="0" izz="0.0514065294384"/>
    </inertial>
  </link>
  
  <link name="link_s">
    <visual>
      <origin xyz="0 0 0" rpy="0 0 0" />
      <geometry>
        <mesh filename="file://$(find yaskawa_description_ros2)/meshes/visual/link_s.dae"/>
      </geometry>
    </visual>
    <collision>
      <origin xyz="0 0 0" rpy="0 0 0" />
      <geometry>
        <mesh filename="file://$(find yaskawa_description_ros2)/meshes/collision/link_s.dae"/>
      </geometry>
    </collision>
    <inertial>
      <mass value="8.36956521739"/>
      <inertia ixx="0.1285284" ixy="0" ixz="0" iyy="0.127697251956" iyz="0" izz="0.0186623672464"/>
     <origin rpy="0.0 0.0 0.0" xyz="0.0 0.0046451930 -0.018976267"/>
    </inertial>
  </link>
  
  <joint name="joint_s" type="revolute">
    <origin xyz="0 0 0.31" rpy="0 0 0" /> 
    <parent link="base_link" />
    <child link="link_s" />
    <axis xyz="0 0 1" />
    <limit lower="${-180.0*deg}" upper="${180.0*deg}" effort="0" velocity="${200.0*deg}" />
    <dynamics damping="0.7" friction="0.7"/>
  </joint>

  <link name="link_l">
    <visual>
      <origin xyz="0 0 0" rpy="0 0 0" />
      <geometry>
        <mesh filename="file://$(find yaskawa_description_ros2)/meshes/visual/link_l.dae"/>
      </geometry>
    </visual>
    <collision>
      <origin xyz="0 0 0" rpy="0 0 0" />
      <geometry>
        <mesh filename="file://$(find yaskawa_description_ros2)/meshes/collision/link_l.dae"/>
      </geometry>
    </collision>
    <inertial>
      <mass value="7.60869565217"/>
      <inertia ixx="0.12248884058" ixy="0" ixz="0" iyy="0.117554616667" iyz="0" izz="0.0177495804348"/>
     <origin rpy="0.0 0.0 0.0" xyz="0.11422130 0.0 0.018935113"/>
    </inertial>
  </link>
  
  <joint name="joint_l" type="revolute">
    <origin xyz="0 0 0" rpy="0 0 0" />
    <parent link="link_s" />
    <child link="link_l" />
    <axis xyz="0 1 0" />
    <limit lower="${-110*deg}" upper="${110*deg}" effort="0" velocity="${200*deg}" />
    <dynamics damping="0.7" friction="0.7"/>
    </joint>

  <link name="link_e">
    <visual>
      <origin xyz="0 0 0" rpy="0 0 0" />
      <geometry>
        <mesh filename="file://$(find yaskawa_description_ros2)/meshes/visual/link_e.dae"/>
      </geometry>
    </visual>
    <collision>
      <origin xyz="0 0 0" rpy="0 0 0" />
      <geometry>
        <mesh filename="file://$(find yaskawa_description_ros2)/meshes/collision/link_e.dae"/>
      </geometry>
    </collision>
    <inertial>
      <mass value="1.30434782609"/>
      <inertia ixx="0.0122899381739" ixy="0" ixz="0" iyy="0.0117127787826" iyz="0" izz="0.00344401234783"/>
   <origin rpy="0.0 0.0 0.0" xyz="0.0 -0.011901001 -0.036023969"/>
    </inertial>
  </link>
  
  <joint name="joint_e" type="revolute">
    <origin xyz="0 0 0.27" rpy="0 0 0" />
    <parent link="link_l" />
    <child link="link_e" />
    <axis xyz="0 0 1" />
    <limit lower="${-170*deg}" upper="${170*deg}" effort="0" velocity="${200*deg}" />
    <dynamics damping="0.7" friction="0.7"/>
  </joint>
  
  <link name="link_u">
    <visual>
      <origin xyz="0 0 0" rpy="0 0 0" />
      <geometry>
        <mesh filename="file://$(find yaskawa_description_ros2)/meshes/visual/link_u.dae"/>
      </geometry>
    </visual>
    <collision>axis
      <origin xyz="0 0 0" rpy="0 0 0" />
      <geometry>
        <mesh filename="file://$(find yaskawa_description_ros2)/meshes/collision/link_u.dae"/>
      </geometry>
    </collision>
    <inertial>
      <mass value="1.08695652174"/>
      <inertia ixx="0.0110207115768" ixy="0" ixz="0" iyy="0.00996803594202" iyz="0" izz="0.00214043853333"/>
     <origin rpy="0.0 0.0 0.0" xyz="0.0 -0.015659426 0.13525753"/>
    </inertial>
  </link>
  
  <joint name="joint_u" type="revolute">
    <origin xyz="0.085 0 0" rpy="0 0 0" />
    <parent link="link_e" />
    <child link="link_u" />
    <axis xyz="0 -1 0" />
    <limit lower="${-90*deg}" upper="${115*deg}" effort="0"  velocity="${200*deg}" />
    <dynamics damping="0.7" friction="0.7"/>
  </joint>

  <link name="link_r">
    <visual>
      <origin xyz="0 0 0" rpy="0 0 0" />
      <geometry>
        <mesh filename="file://$(find yaskawa_description_ros2)/meshes/visual/link_r.dae"/>
      </geometry>
    </visual>
    <collision>
      <origin xyz="0 0 0" rpy="0 0 0" />
      <geometry>
        <mesh filename="file://$(find yaskawa_description_ros2)/meshes/collision/link_r.dae"/>
      </geometry>
    </collision>
    <inertial>
      <mass value="0.978260869565"/>
      <inertia ixx="0.0108400832201" ixy="0" ixz="0" iyy="0.010708873981" iyz="0" izz="0.00140456861413"/>
     <origin rpy="0.0 0.0 0.0" xyz="0.0 -0.011271807 -0.0416"/>
    </inertial>
  </link>
  
  <joint name="joint_r" type="revolute">
    <origin xyz="0.27 0 0.06" rpy="0 0 0" />
    <parent link="link_u" />
    <child link="link_r" />
    <axis xyz="-1 0 0" />
    <limit lower="${-90*deg}" upper="${90*deg}" effort="0" velocity="${200*deg}" />
    <dynamics damping="0.7" friction="0.7"/>
  </joint>

  <link name="link_b">
    <visual>
      <origin xyz="0 0 0" rpy="0 0 0" />
      <geometry>
        <mesh filename="file://$(find yaskawa_description_ros2)/meshes/visual/link_b.dae"/>
      </geometry>
    </visual>
    <collision>
      <origin xyz="0 0 0" rpy="0 0 0" />
      <geometry>
        <mesh filename="file://$(find yaskawa_description_ros2)/meshes/collision/link_b.dae"/>
      </geometry>
    </collision>
    <inertial>
      <mass value="0.869565217391"/>
      <inertia ixx="0.00814341869565" ixy="0" ixz="0" iyy="0.00709473869565" iyz="0" izz="0.000736577391304"/>
     <origin rpy="0.0 0.0 0.0" xyz="0.0 0.0074364051 0.078721289"/>
    </inertial>
  </link>
  
  <joint name="joint_b" type="revolute">
    <origin xyz="0 0 0" rpy="0 0 0" />
    <parent link="link_r" />
    <child link="link_b" />
    <axis xyz="0 -1 0" />
    <limit lower="${-110*deg}" upper="${110*deg}" effort="0" velocity="${230*deg}" />
    <dynamics damping="0.7" friction="0.7"/>
  </joint>

  <link name="link_t">
    <visual>
      <origin xyz="0 0 0" rpy="0 0 0" />
      <geometry>
        <mesh filename="file://$(find yaskawa_description_ros2)/meshes/visual/link_t.dae"/>
      </geometry>
    </visual>
    <collision>
      <origin xyz="0 0 0" rpy="0 0 0" />
      <geometry>
        <mesh filename="file://$(find yaskawa_description_ros2)/meshes/collision/link_t.dae"/>
      </geometry>
    </collision>
    <inertial>
      <mass value="0.54347826087"/>
      <inertia ixx="0.003" ixy="0" ixz="0" iyy="0.003" iyz="0" izz="0.001"/>
     <origin rpy="0.0 0.0 0.0" xyz="0.0 0.0 0.0"/>
    </inertial>
  </link>
  
  <joint name="joint_t" type="revolute">
    <origin xyz="0.134 -0.0078 0" rpy="0 0 0" />
    <parent link="link_b" />
    <child link="link_t" />
    <axis xyz="-1 0 0" />
    <limit lower="${-90*deg}" upper="${90*deg}" effort="0" velocity="${350*deg}" />
    <dynamics damping="0.7" friction="0.7"/>
  </joint>
  
  <link name="tool0" />
  
  <joint name="link_t-tool0" type="fixed" >
    <origin xyz="0.011 0 0" rpy="${-90*deg} ${-90*deg} ${-90*deg}"/>
    <parent link="link_t" />
    <child link="tool0" />
  </joint> 


  <!-- transmission -->
  <!-- transmission -->
  <transmission name="transmission_s">
    <type>transmission_interface/SimpleTransmission</type>
    <joint name="joint_s">
      <hardwareInterface>PositionJointInterface</hardwareInterface>
    </joint>
    <actuator name="motor_s">
      <hardwareInterface>PositionJointInterface</hardwareInterface>
      <mechanicalReduction>300</mechanicalReduction>
    </actuator>
  </transmission>
  <transmission name="transmission_l">
    <type>transmission_interface/SimpleTransmission</type>
    <joint name="joint_l">
      <hardwareInterface>PositionJointInterface</hardwareInterface>
    </joint>
    <actuator name="motor_l">
      <hardwareInterface>PositionJointInterface</hardwareInterface>
      <mechanicalReduction>300</mechanicalReduction>
    </actuator>
  </transmission>
  <transmission name="transmission_e">
    <type>transmission_interface/SimpleTransmission</type>
    <joint name="joint_e">
      <hardwareInterface>PositionJointInterface</hardwareInterface>
    </joint>
    <actuator name="motor_e">
      <hardwareInterface>PositionJointInterface</hardwareInterface>
      <mechanicalReduction>100</mechanicalReduction>
    </actuator>
  </transmission>
  <transmission name="transmission_u">
    <type>transmission_interface/SimpleTransmission</type>
    <joint name="joint_u">
      <hardwareInterface>PositionJointInterface</hardwareInterface>
    </joint>
    <actuator name="motor_u">
      <hardwareInterface>PositionJointInterface</hardwareInterface>
      <mechanicalReduction>50</mechanicalReduction>
    </actuator>
  </transmission>
  <transmission name="transmission_r">
    <type>transmission_interface/SimpleTransmission</type>
    <joint name="joint_r">
      <hardwareInterface>PositionJointInterface</hardwareInterface>
    </joint>
    <actuator name="motor_r">
      <hardwareInterface>PositionJointInterface</hardwareInterface>
      <mechanicalReduction>30</mechanicalReduction>
    </actuator>
  </transmission>
  <transmission name="transmission_b">
    <type>transmission_interface/SimpleTransmission</type>
    <joint name="joint_b">
      <hardwareInterface>PositionJointInterface</hardwareInterface>
    </joint>
    <actuator name="motor_b">
      <hardwareInterface>PositionJointInterface</hardwareInterface>
      <mechanicalReduction>30</mechanicalReduction>
    </actuator>
  </transmission>
  <transmission name="transmission_t">
    <type>transmission_interface/SimpleTransmission</type>
    <joint name="joint_t">
      <hardwareInterface>PositionJointInterface</hardwareInterface>
    </joint>
    <actuator name="motor_t">
      <hardwareInterface>PositionJointInterface</hardwareInterface>
      <mechanicalReduction>10</mechanicalReduction>
    </actuator>
  </transmission>  


</robot>
